<?xml version="1.0" ?>
<!-- =================================================================================== -->
<!-- |    This document was autogenerated by xacro from arm.urdf.xacro                 | -->
<!-- |    EDITING THIS FILE BY HAND IS NOT RECOMMENDED                                 | -->
<!-- =================================================================================== -->
<robot name="arm">
  <!-- ========================= -->
  <!-- PROPERTIES -->
  <!-- ========================= -->
  <!-- ========================= -->
  <!-- MATERIALS -->
  <!-- ========================= -->
  <material name="blue">
    <color rgba="0.2 0.4 0.8 1"/>
  </material>
  <material name="orange">
    <color rgba="0.9 0.4 0.1 1"/>
  </material>
  <!-- ========================= -->
  <!-- MACRO: CYLINDER LINK -->
  <!-- ========================= -->
  <!-- ========================= -->
  <!-- BASE -->
  <!-- ========================= -->
  <link name="base_link">
    <visual>
      <geometry>
        <cylinder length="0.05" radius="0.06"/>
      </geometry>
      <material name="orange"/>
    </visual>
  </link>
  <!-- ========================= -->
  <!-- LINKS -->
  <!-- ========================= -->
  <link name="link_1">
    <visual>
      <!-- center-based geometry -->
      <origin xyz="0 0 0.125"/>
      <geometry>
        <cylinder length="0.25" radius="0.03"/>
      </geometry>
      <material name="blue"/>
    </visual>
    <collision>
      <origin xyz="0 0 0.125"/>
      <geometry>
        <cylinder length="0.25" radius="0.03"/>
      </geometry>
    </collision>
  </link>
  <link name="link_2">
    <visual>
      <!-- center-based geometry -->
      <origin xyz="0 0 0.11"/>
      <geometry>
        <cylinder length="0.22" radius="0.03"/>
      </geometry>
      <material name="blue"/>
    </visual>
    <collision>
      <origin xyz="0 0 0.11"/>
      <geometry>
        <cylinder length="0.22" radius="0.03"/>
      </geometry>
    </collision>
  </link>
  <link name="link_3">
    <visual>
      <!-- center-based geometry -->
      <origin xyz="0 0 0.075"/>
      <geometry>
        <cylinder length="0.15" radius="0.03"/>
      </geometry>
      <material name="blue"/>
    </visual>
    <collision>
      <origin xyz="0 0 0.075"/>
      <geometry>
        <cylinder length="0.15" radius="0.03"/>
      </geometry>
    </collision>
  </link>
  <link name="link_4">
    <visual>
      <!-- center-based geometry -->
      <origin xyz="0 0 0.05"/>
      <geometry>
        <cylinder length="0.1" radius="0.03"/>
      </geometry>
      <material name="blue"/>
    </visual>
    <collision>
      <origin xyz="0 0 0.05"/>
      <geometry>
        <cylinder length="0.1" radius="0.03"/>
      </geometry>
    </collision>
  </link>
  <!-- simple gripper -->
  <link name="gripper">
    <visual>
      <geometry>
        <box size="0.05 0.05 0.05"/>
      </geometry>
      <material name="orange"/>
    </visual>
  </link>
  <!-- ========================= -->
  <!-- JOINTS -->
  <!-- ========================= -->
  <!-- BASE ROTATION -->
  <joint name="joint_1" type="revolute">
    <parent link="base_link"/>
    <child link="link_1"/>
    <origin xyz="0 0 0.05"/>
    <!-- rotate around Z -->
    <axis xyz="0 0 1"/>
    <limit effort="20" lower="-3.14" upper="3.14" velocity="1"/>
  </joint>
  <!-- SHOULDER -->
  <joint name="joint_2" type="revolute">
    <parent link="link_1"/>
    <child link="link_2"/>
    <origin xyz="0 0 0.25"/>
    <!-- pitch -->
    <axis xyz="0 1 0"/>
    <limit effort="20" lower="-1.57" upper="1.57" velocity="1"/>
  </joint>
  <!-- ELBOW -->
  <joint name="joint_3" type="revolute">
    <parent link="link_2"/>
    <child link="link_3"/>
    <origin xyz="0 0 0.22"/>
    <axis xyz="0 1 0"/>
    <limit effort="20" lower="-2.0" upper="2.0" velocity="1"/>
  </joint>
  <!-- WRIST PITCH -->
  <joint name="joint_4" type="revolute">
    <parent link="link_3"/>
    <child link="link_4"/>
    <origin xyz="0 0 0.15"/>
    <axis xyz="0 1 0"/>
    <limit effort="10" lower="-1.57" upper="1.57" velocity="1"/>
  </joint>
  <!-- WRIST ROLL -->
  <joint name="joint_5" type="revolute">
    <parent link="link_4"/>
    <child link="gripper"/>
    <origin xyz="0 0 0.1"/>
    <!-- roll -->
    <axis xyz="1 0 0"/>
    <limit effort="10" lower="-3.14" upper="3.14" velocity="1"/>
  </joint>
</robot>
